Workbook

Sheet Lançamentos
A2: Lançamento de fechamento Verdes Vales
A4: Data do fechamento: | C4: 46310
A6: Preencha apenas os campos amarelos. Salve uma cópia para cada fechamento.
D7: NOTA DE SERVIÇO | F7: NOTA DE CONSUMO — ESTADO
A8: Item | B8: Apartamento | C8: Valor do pacote | D8: Serviço • Prefeitura 30% do pacote | F8: Alimentação • Estado 30% do consumo | G8: Bebidas frias • Estado 70% do consumo (monofásico) | H8: TOTAL DA NOTA DE CONSUMO | I8: Conferência | J8: Situação
A9: =IF(COUNTA(B9:C9)=0,"",1) -> 1 | B9: 01 | C9: 3439.52 | D9: =IF(NOT(ISNUMBER(C9)),"",ROUND(C9*30%,2)) -> 1031.86 | F9: =IF(NOT(ISNUMBER(C9)),"",ROUND(H9*30%,2)) -> 722.3 | G9: =IF(NOT(ISNUMBER(C9)),"",ROUND(H9-F9,2)) -> 1685.36 | H9: =IF(NOT(ISNUMBER(C9)),"",ROUND(C9-D9,2)) -> 2407.66 | I9: =IF(NOT(ISNUMBER(C9)),"",ROUND(C9-SUM(D9,F9:G9),2)) -> 0 | J9: =IF(COUNTA(B9:C9)=0,"",IF(B9="","Falta apartamento",IF(NOT(ISNUMBER(C9)),"Falta valor","Completo"))) -> Completo
A10: =IF(COUNTA(B10:C10)=0,"",2) | D10: =IF(NOT(ISNUMBER(C10)),"",ROUND(C10*30%,2)) | F10: =IF(NOT(ISNUMBER(C10)),"",ROUND(H10*30%,2)) | G10: =IF(NOT(ISNUMBER(C10)),"",ROUND(H10-F10,2)) | H10: =IF(NOT(ISNUMBER(C10)),"",ROUND(C10-D10,2)) | I10: =IF(NOT(ISNUMBER(C10)),"",ROUND(C10-SUM(D10,F10:G10),2)) | J10: =IF(COUNTA(B10:C10)=0,"",IF(B10="","Falta apartamento",IF(NOT(ISNUMBER(C10)),"Falta valor","Completo")))
A11: =IF(COUNTA(B11:C11)=0,"",3) | D11: =IF(NOT(ISNUMBER(C11)),"",ROUND(C11*30%,2)) | F11: =IF(NOT(ISNUMBER(C11)),"",ROUND(H11*30%,2)) | G11: =IF(NOT(ISNUMBER(C11)),"",ROUND(H11-F11,2)) | H11: =IF(NOT(ISNUMBER(C11)),"",ROUND(C11-D11,2)) | I11: =IF(NOT(ISNUMBER(C11)),"",ROUND(C11-SUM(D11,F11:G11),2)) | J11: =IF(COUNTA(B11:C11)=0,"",IF(B11="","Falta apartamento",IF(NOT(ISNUMBER(C11)),"Falta valor","Completo")))
A12: =IF(COUNTA(B12:C12)=0,"",4) | D12: =IF(NOT(ISNUMBER(C12)),"",ROUND(C12*30%,2)) | F12: =IF(NOT(ISNUMBER(C12)),"",ROUND(H12*30%,2)) | G12: =IF(NOT(ISNUMBER(C12)),"",ROUND(H12-F12,2)) | H12: =IF(NOT(ISNUMBER(C12)),"",ROUND(C12-D12,2)) | I12: =IF(NOT(ISNUMBER(C12)),"",ROUND(C12-SUM(D12,F12:G12),2)) | J12: =IF(COUNTA(B12:C12)=0,"",IF(B12="","Falta apartamento",IF(NOT(ISNUMBER(C12)),"Falta valor","Completo")))
A13: =IF(COUNTA(B13:C13)=0,"",5) | D13: =IF(NOT(ISNUMBER(C13)),"",ROUND(C13*30%,2)) | F13: =IF(NOT(ISNUMBER(C13)),"",ROUND(H13*30%,2)) | G13: =IF(NOT(ISNUMBER(C13)),"",ROUND(H13-F13,2)) | H13: =IF(NOT(ISNUMBER(C13)),"",ROUND(C13-D13,2)) | I13: =IF(NOT(ISNUMBER(C13)),"",ROUND(C13-SUM(D13,F13:G13),2)) | J13: =IF(COUNTA(B13:C13)=0,"",IF(B13="","Falta apartamento",IF(NOT(ISNUMBER(C13)),"Falta valor","Completo")))
A14: =IF(COUNTA(B14:C14)=0,"",6) | D14: =IF(NOT(ISNUMBER(C14)),"",ROUND(C14*30%,2)) | F14: =IF(NOT(ISNUMBER(C14)),"",ROUND(H14*30%,2)) | G14: =IF(NOT(ISNUMBER(C14)),"",ROUND(H14-F14,2)) | H14: =IF(NOT(ISNUMBER(C14)),"",ROUND(C14-D14,2)) | I14: =IF(NOT(ISNUMBER(C14)),"",ROUND(C14-SUM(D14,F14:G14),2)) | J14: =IF(COUNTA(B14:C14)=0,"",IF(B14="","Falta apartamento",IF(NOT(ISNUMBER(C14)),"Falta valor","Completo")))
A15: =IF(COUNTA(B15:C15)=0,"",7) | D15: =IF(NOT(ISNUMBER(C15)),"",ROUND(C15*30%,2)) | F15: =IF(NOT(ISNUMBER(C15)),"",ROUND(H15*30%,2)) | G15: =IF(NOT(ISNUMBER(C15)),"",ROUND(H15-F15,2)) | H15: =IF(NOT(ISNUMBER(C15)),"",ROUND(C15-D15,2)) | I15: =IF(NOT(ISNUMBER(C15)),"",ROUND(C15-SUM(D15,F15:G15),2)) | J15: =IF(COUNTA(B15:C15)=0,"",IF(B15="","Falta apartamento",IF(NOT(ISNUMBER(C15)),"Falta valor","Completo")))
A16: =IF(COUNTA(B16:C16)=0,"",8) | D16: =IF(NOT(ISNUMBER(C16)),"",ROUND(C16*30%,2)) | F16: =IF(NOT(ISNUMBER(C16)),"",ROUND(H16*30%,2)) | G16: =IF(NOT(ISNUMBER(C16)),"",ROUND(H16-F16,2)) | H16: =IF(NOT(ISNUMBER(C16)),"",ROUND(C16-D16,2)) | I16: =IF(NOT(ISNUMBER(C16)),"",ROUND(C16-SUM(D16,F16:G16),2)) | J16: =IF(COUNTA(B16:C16)=0,"",IF(B16="","Falta apartamento",IF(NOT(ISNUMBER(C16)),"Falta valor","Completo")))
A17: =IF(COUNTA(B17:C17)=0,"",9) | D17: =IF(NOT(ISNUMBER(C17)),"",ROUND(C17*30%,2)) | F17: =IF(NOT(ISNUMBER(C17)),"",ROUND(H17*30%,2)) | G17: =IF(NOT(ISNUMBER(C17)),"",ROUND(H17-F17,2)) | H17: =IF(NOT(ISNUMBER(C17)),"",ROUND(C17-D17,2)) | I17: =IF(NOT(ISNUMBER(C17)),"",ROUND(C17-SUM(D17,F17:G17),2)) | J17: =IF(COUNTA(B17:C17)=0,"",IF(B17="","Falta apartamento",IF(NOT(ISNUMBER(C17)),"Falta valor","Completo")))
A18: =IF(COUNTA(B18:C18)=0,"",10) | D18: =IF(NOT(ISNUMBER(C18)),"",ROUND(C18*30%,2)) | F18: =IF(NOT(ISNUMBER(C18)),"",ROUND(H18*30%,2)) | G18: =IF(NOT(ISNUMBER(C18)),"",ROUND(H18-F18,2)) | H18: =IF(NOT(ISNUMBER(C18)),"",ROUND(C18-D18,2)) | I18: =IF(NOT(ISNUMBER(C18)),"",ROUND(C18-SUM(D18,F18:G18),2)) | J18: =IF(COUNTA(B18:C18)=0,"",IF(B18="","Falta apartamento",IF(NOT(ISNUMBER(C18)),"Falta valor","Completo")))
A19: =IF(COUNTA(B19:C19)=0,"",11) | D19: =IF(NOT(ISNUMBER(C19)),"",ROUND(C19*30%,2)) | F19: =IF(NOT(ISNUMBER(C19)),"",ROUND(H19*30%,2)) | G19: =IF(NOT(ISNUMBER(C19)),"",ROUND(H19-F19,2)) | H19: =IF(NOT(ISNUMBER(C19)),"",ROUND(C19-D19,2)) | I19: =IF(NOT(ISNUMBER(C19)),"",ROUND(C19-SUM(D19,F19:G19),2)) | J19: =IF(COUNTA(B19:C19)=0,"",IF(B19="","Falta apartamento",IF(NOT(ISNUMBER(C19)),"Falta valor","Completo")))
A20: =IF(COUNTA(B20:C20)=0,"",12) | D20: =IF(NOT(ISNUMBER(C20)),"",ROUND(C20*30%,2)) | F20: =IF(NOT(ISNUMBER(C20)),"",ROUND(H20*30%,2)) | G20: =IF(NOT(ISNUMBER(C20)),"",ROUND(H20-F20,2)) | H20: =IF(NOT(ISNUMBER(C20)),"",ROUND(C20-D20,2)) | I20: =IF(NOT(ISNUMBER(C20)),"",ROUND(C20-SUM(D20,F20:G20),2)) | J20: =IF(COUNTA(B20:C20)=0,"",IF(B20="","Falta apartamento",IF(NOT(ISNUMBER(C20)),"Falta valor","Completo")))
A21: =IF(COUNTA(B21:C21)=0,"",13) | D21: =IF(NOT(ISNUMBER(C21)),"",ROUND(C21*30%,2)) | F21: =IF(NOT(ISNUMBER(C21)),"",ROUND(H21*30%,2)) | G21: =IF(NOT(ISNUMBER(C21)),"",ROUND(H21-F21,2)) | H21: =IF(NOT(ISNUMBER(C21)),"",ROUND(C21-D21,2)) | I21: =IF(NOT(ISNUMBER(C21)),"",ROUND(C21-SUM(D21,F21:G21),2)) | J21: =IF(COUNTA(B21:C21)=0,"",IF(B21="","Falta apartamento",IF(NOT(ISNUMBER(C21)),"Falta valor","Completo")))
A22: =IF(COUNTA(B22:C22)=0,"",14) | D22: =IF(NOT(ISNUMBER(C22)),"",ROUND(C22*30%,2)) | F22: =IF(NOT(ISNUMBER(C22)),"",ROUND(H22*30%,2)) | G22: =IF(NOT(ISNUMBER(C22)),"",ROUND(H22-F22,2)) | H22: =IF(NOT(ISNUMBER(C22)),"",ROUND(C22-D22,2)) | I22: =IF(NOT(ISNUMBER(C22)),"",ROUND(C22-SUM(D22,F22:G22),2)) | J22: =IF(COUNTA(B22:C22)=0,"",IF(B22="","Falta apartamento",IF(NOT(ISNUMBER(C22)),"Falta valor","Completo")))
A23: =IF(COUNTA(B23:C23)=0,"",15) | D23: =IF(NOT(ISNUMBER(C23)),"",ROUND(C23*30%,2)) | F23: =IF(NOT(ISNUMBER(C23)),"",ROUND(H23*30%,2)) | G23: =IF(NOT(ISNUMBER(C23)),"",ROUND(H23-F23,2)) | H23: =IF(NOT(ISNUMBER(C23)),"",ROUND(C23-D23,2)) | I23: =IF(NOT(ISNUMBER(C23)),"",ROUND(C23-SUM(D23,F23:G23),2)) | J23: =IF(COUNTA(B23:C23)=0,"",IF(B23="","Falta apartamento",IF(NOT(ISNUMBER(C23)),"Falta valor","Completo")))
A24: =IF(COUNTA(B24:C24)=0,"",16) | D24: =IF(NOT(ISNUMBER(C24)),"",ROUND(C24*30%,2)) | F24: =IF(NOT(ISNUMBER(C24)),"",ROUND(H24*30%,2)) | G24: =IF(NOT(ISNUMBER(C24)),"",ROUND(H24-F24,2)) | H24: =IF(NOT(ISNUMBER(C24)),"",ROUND(C24-D24,2)) | I24: =IF(NOT(ISNUMBER(C24)),"",ROUND(C24-SUM(D24,F24:G24),2)) | J24: =IF(COUNTA(B24:C24)=0,"",IF(B24="","Falta apartamento",IF(NOT(ISNUMBER(C24)),"Falta valor","Completo")))
A25: =IF(COUNTA(B25:C25)=0,"",17) | D25: =IF(NOT(ISNUMBER(C25)),"",ROUND(C25*30%,2)) | F25: =IF(NOT(ISNUMBER(C25)),"",ROUND(H25*30%,2)) | G25: =IF(NOT(ISNUMBER(C25)),"",ROUND(H25-F25,2)) | H25: =IF(NOT(ISNUMBER(C25)),"",ROUND(C25-D25,2)) | I25: =IF(NOT(ISNUMBER(C25)),"",ROUND(C25-SUM(D25,F25:G25),2)) | J25: =IF(COUNTA(B25:C25)=0,"",IF(B25="","Falta apartamento",IF(NOT(ISNUMBER(C25)),"Falta valor","Completo")))
A26: =IF(COUNTA(B26:C26)=0,"",18) | D26: =IF(NOT(ISNUMBER(C26)),"",ROUND(C26*30%,2)) | F26: =IF(NOT(ISNUMBER(C26)),"",ROUND(H26*30%,2)) | G26: =IF(NOT(ISNUMBER(C26)),"",ROUND(H26-F26,2)) | H26: =IF(NOT(ISNUMBER(C26)),"",ROUND(C26-D26,2)) | I26: =IF(NOT(ISNUMBER(C26)),"",ROUND(C26-SUM(D26,F26:G26),2)) | J26: =IF(COUNTA(B26:C26)=0,"",IF(B26="","Falta apartamento",IF(NOT(ISNUMBER(C26)),"Falta valor","Completo")))
A27: =IF(COUNTA(B27:C27)=0,"",19) | D27: =IF(NOT(ISNUMBER(C27)),"",ROUND(C27*30%,2)) | F27: =IF(NOT(ISNUMBER(C27)),"",ROUND(H27*30%,2)) | G27: =IF(NOT(ISNUMBER(C27)),"",ROUND(H27-F27,2)) | H27: =IF(NOT(ISNUMBER(C27)),"",ROUND(C27-D27,2)) | I27: =IF(NOT(ISNUMBER(C27)),"",ROUND(C27-SUM(D27,F27:G27),2)) | J27: =IF(COUNTA(B27:C27)=0,"",IF(B27="","Falta apartamento",IF(NOT(ISNUMBER(C27)),"Falta valor","Completo")))
A28: =IF(COUNTA(B28:C28)=0,"",20) | D28: =IF(NOT(ISNUMBER(C28)),"",ROUND(C28*30%,2)) | F28: =IF(NOT(ISNUMBER(C28)),"",ROUND(H28*30%,2)) | G28: =IF(NOT(ISNUMBER(C28)),"",ROUND(H28-F28,2)) | H28: =IF(NOT(ISNUMBER(C28)),"",ROUND(C28-D28,2)) | I28: =IF(NOT(ISNUMBER(C28)),"",ROUND(C28-SUM(D28,F28:G28),2)) | J28: =IF(COUNTA(B28:C28)=0,"",IF(B28="","Falta apartamento",IF(NOT(ISNUMBER(C28)),"Falta valor","Completo")))
A29: =IF(COUNTA(B29:C29)=0,"",21) | D29: =IF(NOT(ISNUMBER(C29)),"",ROUND(C29*30%,2)) | F29: =IF(NOT(ISNUMBER(C29)),"",ROUND(H29*30%,2)) | G29: =IF(NOT(ISNUMBER(C29)),"",ROUND(H29-F29,2)) | H29: =IF(NOT(ISNUMBER(C29)),"",ROUND(C29-D29,2)) | I29: =IF(NOT(ISNUMBER(C29)),"",ROUND(C29-SUM(D29,F29:G29),2)) | J29: =IF(COUNTA(B29:C29)=0,"",IF(B29="","Falta apartamento",IF(NOT(ISNUMBER(C29)),"Falta valor","Completo")))
A30: =IF(COUNTA(B30:C30)=0,"",22) | D30: =IF(NOT(ISNUMBER(C30)),"",ROUND(C30*30%,2)) | F30: =IF(NOT(ISNUMBER(C30)),"",ROUND(H30*30%,2)) | G30: =IF(NOT(ISNUMBER(C30)),"",ROUND(H30-F30,2)) | H30: =IF(NOT(ISNUMBER(C30)),"",ROUND(C30-D30,2)) | I30: =IF(NOT(ISNUMBER(C30)),"",ROUND(C30-SUM(D30,F30:G30),2)) | J30: =IF(COUNTA(B30:C30)=0,"",IF(B30="","Falta apartamento",IF(NOT(ISNUMBER(C30)),"Falta valor","Completo")))
A31: =IF(COUNTA(B31:C31)=0,"",23) | D31: =IF(NOT(ISNUMBER(C31)),"",ROUND(C31*30%,2)) | F31: =IF(NOT(ISNUMBER(C31)),"",ROUND(H31*30%,2)) | G31: =IF(NOT(ISNUMBER(C31)),"",ROUND(H31-F31,2)) | H31: =IF(NOT(ISNUMBER(C31)),"",ROUND(C31-D31,2)) | I31: =IF(NOT(ISNUMBER(C31)),"",ROUND(C31-SUM(D31,F31:G31),2)) | J31: =IF(COUNTA(B31:C31)=0,"",IF(B31="","Falta apartamento",IF(NOT(ISNUMBER(C31)),"Falta valor","Completo")))
A32: =IF(COUNTA(B32:C32)=0,"",24) | D32: =IF(NOT(ISNUMBER(C32)),"",ROUND(C32*30%,2)) | F32: =IF(NOT(ISNUMBER(C32)),"",ROUND(H32*30%,2)) | G32: =IF(NOT(ISNUMBER(C32)),"",ROUND(H32-F32,2)) | H32: =IF(NOT(ISNUMBER(C32)),"",ROUND(C32-D32,2)) | I32: =IF(NOT(ISNUMBER(C32)),"",ROUND(C32-SUM(D32,F32:G32),2)) | J32: =IF(COUNTA(B32:C32)=0,"",IF(B32="","Falta apartamento",IF(NOT(ISNUMBER(C32)),"Falta valor","Completo")))
A33: =IF(COUNTA(B33:C33)=0,"",25) | D33: =IF(NOT(ISNUMBER(C33)),"",ROUND(C33*30%,2)) | F33: =IF(NOT(ISNUMBER(C33)),"",ROUND(H33*30%,2)) | G33: =IF(NOT(ISNUMBER(C33)),"",ROUND(H33-F33,2)) | H33: =IF(NOT(ISNUMBER(C33)),"",ROUND(C33-D33,2)) | I33: =IF(NOT(ISNUMBER(C33)),"",ROUND(C33-SUM(D33,F33:G33),2)) | J33: =IF(COUNTA(B33:C33)=0,"",IF(B33="","Falta apartamento",IF(NOT(ISNUMBER(C33)),"Falta valor","Completo")))
A34: =IF(COUNTA(B34:C34)=0,"",26) | D34: =IF(NOT(ISNUMBER(C34)),"",ROUND(C34*30%,2)) | F34: =IF(NOT(ISNUMBER(C34)),"",ROUND(H34*30%,2)) | G34: =IF(NOT(ISNUMBER(C34)),"",ROUND(H34-F34,2)) | H34: =IF(NOT(ISNUMBER(C34)),"",ROUND(C34-D34,2)) | I34: =IF(NOT(ISNUMBER(C34)),"",ROUND(C34-SUM(D34,F34:G34),2)) | J34: =IF(COUNTA(B34:C34)=0,"",IF(B34="","Falta apartamento",IF(NOT(ISNUMBER(C34)),"Falta valor","Completo")))
A35: =IF(COUNTA(B35:C35)=0,"",27) | D35: =IF(NOT(ISNUMBER(C35)),"",ROUND(C35*30%,2)) | F35: =IF(NOT(ISNUMBER(C35)),"",ROUND(H35*30%,2)) | G35: =IF(NOT(ISNUMBER(C35)),"",ROUND(H35-F35,2)) | H35: =IF(NOT(ISNUMBER(C35)),"",ROUND(C35-D35,2)) | I35: =IF(NOT(ISNUMBER(C35)),"",ROUND(C35-SUM(D35,F35:G35),2)) | J35: =IF(COUNTA(B35:C35)=0,"",IF(B35="","Falta apartamento",IF(NOT(ISNUMBER(C35)),"Falta valor","Completo")))
A36: =IF(COUNTA(B36:C36)=0,"",28) | D36: =IF(NOT(ISNUMBER(C36)),"",ROUND(C36*30%,2)) | F36: =IF(NOT(ISNUMBER(C36)),"",ROUND(H36*30%,2)) | G36: =IF(NOT(ISNUMBER(C36)),"",ROUND(H36-F36,2)) | H36: =IF(NOT(ISNUMBER(C36)),"",ROUND(C36-D36,2)) | I36: =IF(NOT(ISNUMBER(C36)),"",ROUND(C36-SUM(D36,F36:G36),2)) | J36: =IF(COUNTA(B36:C36)=0,"",IF(B36="","Falta apartamento",IF(NOT(ISNUMBER(C36)),"Falta valor","Completo")))
A37: =IF(COUNTA(B37:C37)=0,"",29) | D37: =IF(NOT(ISNUMBER(C37)),"",ROUND(C37*30%,2)) | F37: =IF(NOT(ISNUMBER(C37)),"",ROUND(H37*30%,2)) | G37: =IF(NOT(ISNUMBER(C37)),"",ROUND(H37-F37,2)) | H37: =IF(NOT(ISNUMBER(C37)),"",ROUND(C37-D37,2)) | I37: =IF(NOT(ISNUMBER(C37)),"",ROUND(C37-SUM(D37,F37:G37),2)) | J37: =IF(COUNTA(B37:C37)=0,"",IF(B37="","Falta apartamento",IF(NOT(ISNUMBER(C37)),"Falta valor","Completo")))
A38: =IF(COUNTA(B38:C38)=0,"",30) | D38: =IF(NOT(ISNUMBER(C38)),"",ROUND(C38*30%,2)) | F38: =IF(NOT(ISNUMBER(C38)),"",ROUND(H38*30%,2)) | G38: =IF(NOT(ISNUMBER(C38)),"",ROUND(H38-F38,2)) | H38: =IF(NOT(ISNUMBER(C38)),"",ROUND(C38-D38,2)) | I38: =IF(NOT(ISNUMBER(C38)),"",ROUND(C38-SUM(D38,F38:G38),2)) | J38: =IF(COUNTA(B38:C38)=0,"",IF(B38="","Falta apartamento",IF(NOT(ISNUMBER(C38)),"Falta valor","Completo")))
A39: =IF(COUNTA(B39:C39)=0,"",31) | D39: =IF(NOT(ISNUMBER(C39)),"",ROUND(C39*30%,2)) | F39: =IF(NOT(ISNUMBER(C39)),"",ROUND(H39*30%,2)) | G39: =IF(NOT(ISNUMBER(C39)),"",ROUND(H39-F39,2)) | H39: =IF(NOT(ISNUMBER(C39)),"",ROUND(C39-D39,2)) | I39: =IF(NOT(ISNUMBER(C39)),"",ROUND(C39-SUM(D39,F39:G39),2)) | J39: =IF(COUNTA(B39:C39)=0,"",IF(B39="","Falta apartamento",IF(NOT(ISNUMBER(C39)),"Falta valor","Completo")))
A40: =IF(COUNTA(B40:C40)=0,"",32) | D40: =IF(NOT(ISNUMBER(C40)),"",ROUND(C40*30%,2)) | F40: =IF(NOT(ISNUMBER(C40)),"",ROUND(H40*30%,2)) | G40: =IF(NOT(ISNUMBER(C40)),"",ROUND(H40-F40,2)) | H40: =IF(NOT(ISNUMBER(C40)),"",ROUND(C40-D40,2)) | I40: =IF(NOT(ISNUMBER(C40)),"",ROUND(C40-SUM(D40,F40:G40),2)) | J40: =IF(COUNTA(B40:C40)=0,"",IF(B40="","Falta apartamento",IF(NOT(ISNUMBER(C40)),"Falta valor","Completo")))
A41: =IF(COUNTA(B41:C41)=0,"",33) | D41: =IF(NOT(ISNUMBER(C41)),"",ROUND(C41*30%,2)) | F41: =IF(NOT(ISNUMBER(C41)),"",ROUND(H41*30%,2)) | G41: =IF(NOT(ISNUMBER(C41)),"",ROUND(H41-F41,2)) | H41: =IF(NOT(ISNUMBER(C41)),"",ROUND(C41-D41,2)) | I41: =IF(NOT(ISNUMBER(C41)),"",ROUND(C41-SUM(D41,F41:G41),2)) | J41: =IF(COUNTA(B41:C41)=0,"",IF(B41="","Falta apartamento",IF(NOT(ISNUMBER(C41)),"Falta valor","Completo")))
A42: =IF(COUNTA(B42:C42)=0,"",34) | D42: =IF(NOT(ISNUMBER(C42)),"",ROUND(C42*30%,2)) | F42: =IF(NOT(ISNUMBER(C42)),"",ROUND(H42*30%,2)) | G42: =IF(NOT(ISNUMBER(C42)),"",ROUND(H42-F42,2)) | H42: =IF(NOT(ISNUMBER(C42)),"",ROUND(C42-D42,2)) | I42: =IF(NOT(ISNUMBER(C42)),"",ROUND(C42-SUM(D42,F42:G42),2)) | J42: =IF(COUNTA(B42:C42)=0,"",IF(B42="","Falta apartamento",IF(NOT(ISNUMBER(C42)),"Falta valor","Completo")))
A43: =IF(COUNTA(B43:C43)=0,"",35) | D43: =IF(NOT(ISNUMBER(C43)),"",ROUND(C43*30%,2)) | F43: =IF(NOT(ISNUMBER(C43)),"",ROUND(H43*30%,2)) | G43: =IF(NOT(ISNUMBER(C43)),"",ROUND(H43-F43,2)) | H43: =IF(NOT(ISNUMBER(C43)),"",ROUND(C43-D43,2)) | I43: =IF(NOT(ISNUMBER(C43)),"",ROUND(C43-SUM(D43,F43:G43),2)) | J43: =IF(COUNTA(B43:C43)=0,"",IF(B43="","Falta apartamento",IF(NOT(ISNUMBER(C43)),"Falta valor","Completo")))
...

Sheet Fechamento
A2: Lançamento de fechamento Verdes Vales
A4: Data do fechamento: | C4: =IF(Lançamentos!C4="","",Lançamentos!C4) -> 46310
B5: TOTAL GERAL | C5: =SUM(Lançamentos!C9:C1008) -> 3439.52 | D5: =SUM(Lançamentos!D9:D1008) -> 1031.86 | F5: =SUM(Lançamentos!F9:F1008) -> 722.3 | G5: =SUM(Lançamentos!G9:G1008) -> 1685.36 | H5: =SUM(Lançamentos!H9:H1008) -> 2407.66
A6: Valores acumulados por lançamento. Alimentação + bebidas frias = nota de consumo.
D7: NOTA DE SERVIÇO | F7: NOTA DE CONSUMO — ESTADO
A8: Item | B8: Apartamento | C8: Pacote lançado | D8: Serviço acumulado Prefeitura | F8: Alimentação acumulada Estado | G8: Bebidas frias acumuladas Estado (monofásico) | H8: NOTA DE CONSUMO ACUMULADA | I8: FATURAMENTO ACUMULADO | J8: Situação
A9: =IF(ISNUMBER(Lançamentos!A9),Lançamentos!A9,"") -> 1 | B9: =IF(Lançamentos!B9="","",Lançamentos!B9) -> 01 | C9: =IF(ISNUMBER(Lançamentos!C9),Lançamentos!C9,"") -> 3439.52 | D9: =IF(A9="","",SUM(Lançamentos!D$9:D9)) -> 1031.86 | F9: =IF(A9="","",SUM(Lançamentos!F$9:F9)) -> 722.3 | G9: =IF(A9="","",SUM(Lançamentos!G$9:G9)) -> 1685.36 | H9: =IF(A9="","",SUM(Lançamentos!H$9:H9)) -> 2407.66 | I9: =IF(A9="","",SUM(Lançamentos!C$9:C9)) -> 3439.52 | J9: =IF(Lançamentos!J9="","",Lançamentos!J9) -> Completo
A10: =IF(ISNUMBER(Lançamentos!A10),Lançamentos!A10,"") | B10: =IF(Lançamentos!B10="","",Lançamentos!B10) | C10: =IF(ISNUMBER(Lançamentos!C10),Lançamentos!C10,"") | D10: =IF(A10="","",SUM(Lançamentos!D$9:D10)) | F10: =IF(A10="","",SUM(Lançamentos!F$9:F10)) | G10: =IF(A10="","",SUM(Lançamentos!G$9:G10)) | H10: =IF(A10="","",SUM(Lançamentos!H$9:H10)) | I10: =IF(A10="","",SUM(Lançamentos!C$9:C10)) | J10: =IF(Lançamentos!J10="","",Lançamentos!J10)
A11: =IF(ISNUMBER(Lançamentos!A11),Lançamentos!A11,"") | B11: =IF(Lançamentos!B11="","",Lançamentos!B11) | C11: =IF(ISNUMBER(Lançamentos!C11),Lançamentos!C11,"") | D11: =IF(A11="","",SUM(Lançamentos!D$9:D11)) | F11: =IF(A11="","",SUM(Lançamentos!F$9:F11)) | G11: =IF(A11="","",SUM(Lançamentos!G$9:G11)) | H11: =IF(A11="","",SUM(Lançamentos!H$9:H11)) | I11: =IF(A11="","",SUM(Lançamentos!C$9:C11)) | J11: =IF(Lançamentos!J11="","",Lançamentos!J11)
A12: =IF(ISNUMBER(Lançamentos!A12),Lançamentos!A12,"") | B12: =IF(Lançamentos!B12="","",Lançamentos!B12) | C12: =IF(ISNUMBER(Lançamentos!C12),Lançamentos!C12,"") | D12: =IF(A12="","",SUM(Lançamentos!D$9:D12)) | F12: =IF(A12="","",SUM(Lançamentos!F$9:F12)) | G12: =IF(A12="","",SUM(Lançamentos!G$9:G12)) | H12: =IF(A12="","",SUM(Lançamentos!H$9:H12)) | I12: =IF(A12="","",SUM(Lançamentos!C$9:C12)) | J12: =IF(Lançamentos!J12="","",Lançamentos!J12)
A13: =IF(ISNUMBER(Lançamentos!A13),Lançamentos!A13,"") | B13: =IF(Lançamentos!B13="","",Lançamentos!B13) | C13: =IF(ISNUMBER(Lançamentos!C13),Lançamentos!C13,"") | D13: =IF(A13="","",SUM(Lançamentos!D$9:D13)) | F13: =IF(A13="","",SUM(Lançamentos!F$9:F13)) | G13: =IF(A13="","",SUM(Lançamentos!G$9:G13)) | H13: =IF(A13="","",SUM(Lançamentos!H$9:H13)) | I13: =IF(A13="","",SUM(Lançamentos!C$9:C13)) | J13: =IF(Lançamentos!J13="","",Lançamentos!J13)
A14: =IF(ISNUMBER(Lançamentos!A14),Lançamentos!A14,"") | B14: =IF(Lançamentos!B14="","",Lançamentos!B14) | C14: =IF(ISNUMBER(Lançamentos!C14),Lançamentos!C14,"") | D14: =IF(A14="","",SUM(Lançamentos!D$9:D14)) | F14: =IF(A14="","",SUM(Lançamentos!F$9:F14)) | G14: =IF(A14="","",SUM(Lançamentos!G$9:G14)) | H14: =IF(A14="","",SUM(Lançamentos!H$9:H14)) | I14: =IF(A14="","",SUM(Lançamentos!C$9:C14)) | J14: =IF(Lançamentos!J14="","",Lançamentos!J14)
A15: =IF(ISNUMBER(Lançamentos!A15),Lançamentos!A15,"") | B15: =IF(Lançamentos!B15="","",Lançamentos!B15) | C15: =IF(ISNUMBER(Lançamentos!C15),Lançamentos!C15,"") | D15: =IF(A15="","",SUM(Lançamentos!D$9:D15)) | F15: =IF(A15="","",SUM(Lançamentos!F$9:F15)) | G15: =IF(A15="","",SUM(Lançamentos!G$9:G15)) | H15: =IF(A15="","",SUM(Lançamentos!H$9:H15)) | I15: =IF(A15="","",SUM(Lançamentos!C$9:C15)) | J15: =IF(Lançamentos!J15="","",Lançamentos!J15)
A16: =IF(ISNUMBER(Lançamentos!A16),Lançamentos!A16,"") | B16: =IF(Lançamentos!B16="","",Lançamentos!B16) | C16: =IF(ISNUMBER(Lançamentos!C16),Lançamentos!C16,"") | D16: =IF(A16="","",SUM(Lançamentos!D$9:D16)) | F16: =IF(A16="","",SUM(Lançamentos!F$9:F16)) | G16: =IF(A16="","",SUM(Lançamentos!G$9:G16)) | H16: =IF(A16="","",SUM(Lançamentos!H$9:H16)) | I16: =IF(A16="","",SUM(Lançamentos!C$9:C16)) | J16: =IF(Lançamentos!J16="","",Lançamentos!J16)
A17: =IF(ISNUMBER(Lançamentos!A17),Lançamentos!A17,"") | B17: =IF(Lançamentos!B17="","",Lançamentos!B17) | C17: =IF(ISNUMBER(Lançamentos!C17),Lançamentos!C17,"") | D17: =IF(A17="","",SUM(Lançamentos!D$9:D17)) | F17: =IF(A17="","",SUM(Lançamentos!F$9:F17)) | G17: =IF(A17="","",SUM(Lançamentos!G$9:G17)) | H17: =IF(A17="","",SUM(Lançamentos!H$9:H17)) | I17: =IF(A17="","",SUM(Lançamentos!C$9:C17)) | J17: =IF(Lançamentos!J17="","",Lançamentos!J17)
A18: =IF(ISNUMBER(Lançamentos!A18),Lançamentos!A18,"") | B18: =IF(Lançamentos!B18="","",Lançamentos!B18) | C18: =IF(ISNUMBER(Lançamentos!C18),Lançamentos!C18,"") | D18: =IF(A18="","",SUM(Lançamentos!D$9:D18)) | F18: =IF(A18="","",SUM(Lançamentos!F$9:F18)) | G18: =IF(A18="","",SUM(Lançamentos!G$9:G18)) | H18: =IF(A18="","",SUM(Lançamentos!H$9:H18)) | I18: =IF(A18="","",SUM(Lançamentos!C$9:C18)) | J18: =IF(Lançamentos!J18="","",Lançamentos!J18)
A19: =IF(ISNUMBER(Lançamentos!A19),Lançamentos!A19,"") | B19: =IF(Lançamentos!B19="","",Lançamentos!B19) | C19: =IF(ISNUMBER(Lançamentos!C19),Lançamentos!C19,"") | D19: =IF(A19="","",SUM(Lançamentos!D$9:D19)) | F19: =IF(A19="","",SUM(Lançamentos!F$9:F19)) | G19: =IF(A19="","",SUM(Lançamentos!G$9:G19)) | H19: =IF(A19="","",SUM(Lançamentos!H$9:H19)) | I19: =IF(A19="","",SUM(Lançamentos!C$9:C19)) | J19: =IF(Lançamentos!J19="","",Lançamentos!J19)
A20: =IF(ISNUMBER(Lançamentos!A20),Lançamentos!A20,"") | B20: =IF(Lançamentos!B20="","",Lançamentos!B20) | C20: =IF(ISNUMBER(Lançamentos!C20),Lançamentos!C20,"") | D20: =IF(A20="","",SUM(Lançamentos!D$9:D20)) | F20: =IF(A20="","",SUM(Lançamentos!F$9:F20)) | G20: =IF(A20="","",SUM(Lançamentos!G$9:G20)) | H20: =IF(A20="","",SUM(Lançamentos!H$9:H20)) | I20: =IF(A20="","",SUM(Lançamentos!C$9:C20)) | J20: =IF(Lançamentos!J20="","",Lançamentos!J20)
... A1008: =IF(ISNUMBER(Lançamentos!A1008),Lançamentos!A1008,"") | B1008: =IF(Lançamentos!B1008="","",Lançamentos!B1008) | C1008: =IF(ISNUMBER(Lançamentos!C1008),Lançamentos!C1008,"") | D1008: =IF(A1008="","",SUM(Lançamentos!D$9:D1008)) | F1008: =IF(A1008="","",SUM(Lançamentos!F$9:F1008)) | G1008: =IF(A1008="","",SUM(Lançamentos!G$9:G1008)) | H1008: =IF(A1008="","",SUM(Lançamentos!H$9:H1008)) | I1008: =IF(A1008="","",SUM(Lançamentos!C$9:C1008)) | J1008: =IF(Lançamentos!J1008="","",Lançamentos!J1008)
